2024-02-26 21:03:42,433 ERROR: Exception on /register [POST] [in C:\Users\User\Desktop\daveblog\venv\Lib\site-packages\flask\app.py:828]
Traceback (most recent call last):
  File "C:\Users\User\Desktop\daveblog\venv\Lib\site-packages\sqlalchemy\engine\base.py", line 1960, in _exec_single_context
    self.dialect.do_execute(
  File "C:\Users\User\Desktop\daveblog\venv\Lib\site-packages\sqlalchemy\engine\default.py", line 924, in do_execute
    cursor.execute(statement, parameters)
sqlite3.OperationalError: no such table: user

The above exception was the direct cause of the following exception:

Traceback (most recent call last):
  File "C:\Users\User\Desktop\daveblog\venv\Lib\site-packages\flask\app.py", line 1463, in wsgi_app
    response = self.full_dispatch_request()
               ^^^^^^^^^^^^^^^^^^^^^^^^^^^^
  File "C:\Users\User\Desktop\daveblog\venv\Lib\site-packages\flask\app.py", line 872, in full_dispatch_request
    rv = self.handle_user_exception(e)
         ^^^^^^^^^^^^^^^^^^^^^^^^^^^^^
  File "C:\Users\User\Desktop\daveblog\venv\Lib\site-packages\flask\app.py", line 870, in full_dispatch_request
    rv = self.dispatch_request()
         ^^^^^^^^^^^^^^^^^^^^^^^
  File "C:\Users\User\Desktop\daveblog\venv\Lib\site-packages\flask\app.py", line 855, in dispatch_request
    return self.ensure_sync(self.view_functions[rule.endpoint])(**view_args)  # type: ignore[no-any-return]
           ^^^^^^^^^^^^^^^^^^^^^^^^^^^^^^^^^^^^^^^^^^^^^^^^^^^^^^^^^^^^^^^^^
  File "C:\Users\User\Desktop\daveblog\app\routes.py", line 71, in register
    if form.validate_on_submit():
       ^^^^^^^^^^^^^^^^^^^^^^^^^
  File "C:\Users\User\Desktop\daveblog\venv\Lib\site-packages\flask_wtf\form.py", line 86, in validate_on_submit
    return self.is_submitted() and self.validate(extra_validators=extra_validators)
                                   ^^^^^^^^^^^^^^^^^^^^^^^^^^^^^^^^^^^^^^^^^^^^^^^^
  File "C:\Users\User\Desktop\daveblog\venv\Lib\site-packages\wtforms\form.py", line 329, in validate
    return super().validate(extra)
           ^^^^^^^^^^^^^^^^^^^^^^^
  File "C:\Users\User\Desktop\daveblog\venv\Lib\site-packages\wtforms\form.py", line 146, in validate
    if not field.validate(self, extra):
           ^^^^^^^^^^^^^^^^^^^^^^^^^^^
  File "C:\Users\User\Desktop\daveblog\venv\Lib\site-packages\wtforms\fields\core.py", line 246, in validate
    stop_validation = self._run_validation_chain(form, chain)
                      ^^^^^^^^^^^^^^^^^^^^^^^^^^^^^^^^^^^^^^^
  File "C:\Users\User\Desktop\daveblog\venv\Lib\site-packages\wtforms\fields\core.py", line 266, in _run_validation_chain
    validator(form, self)
  File "C:\Users\User\Desktop\daveblog\app\forms.py", line 25, in validate_username
    user = db.session.scalar(sa.select(User).where(
           ^^^^^^^^^^^^^^^^^^^^^^^^^^^^^^^^^^^^^^^^
  File "C:\Users\User\Desktop\daveblog\venv\Lib\site-packages\sqlalchemy\orm\scoping.py", line 1843, in scalar
    return self._proxied.scalar(
           ^^^^^^^^^^^^^^^^^^^^^
  File "C:\Users\User\Desktop\daveblog\venv\Lib\site-packages\sqlalchemy\orm\session.py", line 2354, in scalar
    return self._execute_internal(
           ^^^^^^^^^^^^^^^^^^^^^^^
  File "C:\Users\User\Desktop\daveblog\venv\Lib\site-packages\sqlalchemy\orm\session.py", line 2191, in _execute_internal
    result: Result[Any] = compile_state_cls.orm_execute_statement(
                          ^^^^^^^^^^^^^^^^^^^^^^^^^^^^^^^^^^^^^^^^
  File "C:\Users\User\Desktop\daveblog\venv\Lib\site-packages\sqlalchemy\orm\context.py", line 293, in orm_execute_statement
    result = conn.execute(
             ^^^^^^^^^^^^^
  File "C:\Users\User\Desktop\daveblog\venv\Lib\site-packages\sqlalchemy\engine\base.py", line 1408, in execute
    return meth(
           ^^^^^
  File "C:\Users\User\Desktop\daveblog\venv\Lib\site-packages\sqlalchemy\sql\elements.py", line 513, in _execute_on_connection
    return connection._execute_clauseelement(
           ^^^^^^^^^^^^^^^^^^^^^^^^^^^^^^^^^^
  File "C:\Users\User\Desktop\daveblog\venv\Lib\site-packages\sqlalchemy\engine\base.py", line 1630, in _execute_clauseelement
    ret = self._execute_context(
          ^^^^^^^^^^^^^^^^^^^^^^
  File "C:\Users\User\Desktop\daveblog\venv\Lib\site-packages\sqlalchemy\engine\base.py", line 1839, in _execute_context
    return self._exec_single_context(
           ^^^^^^^^^^^^^^^^^^^^^^^^^^
  File "C:\Users\User\Desktop\daveblog\venv\Lib\site-packages\sqlalchemy\engine\base.py", line 1979, in _exec_single_context
    self._handle_dbapi_exception(
  File "C:\Users\User\Desktop\daveblog\venv\Lib\site-packages\sqlalchemy\engine\base.py", line 2335, in _handle_dbapi_exception
    raise sqlalchemy_exception.with_traceback(exc_info[2]) from e
  File "C:\Users\User\Desktop\daveblog\venv\Lib\site-packages\sqlalchemy\engine\base.py", line 1960, in _exec_single_context
    self.dialect.do_execute(
  File "C:\Users\User\Desktop\daveblog\venv\Lib\site-packages\sqlalchemy\engine\default.py", line 924, in do_execute
    cursor.execute(statement, parameters)
sqlalchemy.exc.OperationalError: (sqlite3.OperationalError) no such table: user
[SQL: SELECT user.id, user.username, user.email, user.password_hash, user.about_me, user.last_seen 
FROM user 
WHERE user.username = ?]
[parameters: ('susan',)]
(Background on this error at: https://sqlalche.me/e/20/e3q8)
2024-02-26 21:06:32,023 INFO: Microblog startup [in C:\Users\User\Desktop\daveblog\app\__init__.py:47]
2024-02-26 21:07:14,281 INFO: Microblog startup [in C:\Users\User\Desktop\daveblog\app\__init__.py:47]
2024-02-26 21:07:38,405 INFO: Microblog startup [in C:\Users\User\Desktop\daveblog\app\__init__.py:47]
2024-02-26 21:07:55,785 INFO: Microblog startup [in C:\Users\User\Desktop\daveblog\app\__init__.py:47]
2024-02-26 21:08:26,832 INFO: Microblog startup [in C:\Users\User\Desktop\daveblog\app\__init__.py:47]
2024-02-26 21:09:12,190 INFO: Microblog startup [in C:\Users\User\Desktop\daveblog\app\__init__.py:47]
2024-02-26 21:09:37,674 INFO: Microblog startup [in C:\Users\User\Desktop\daveblog\app\__init__.py:47]
2024-02-26 21:13:23,689 INFO: Microblog startup [in C:\Users\User\Desktop\daveblog\app\__init__.py:47]
2024-02-26 21:13:35,219 INFO: Microblog startup [in C:\Users\User\Desktop\daveblog\app\__init__.py:47]
2024-02-26 21:14:26,690 INFO: Microblog startup [in C:\Users\User\Desktop\daveblog\app\__init__.py:47]
2024-02-26 21:22:52,252 INFO: Microblog startup [in C:\Users\User\Desktop\daveblog\app\__init__.py:47]
2024-02-26 21:30:49,512 ERROR: Exception on /reset_password_request [GET] [in C:\Users\User\Desktop\daveblog\venv\Lib\site-packages\flask\app.py:828]
Traceback (most recent call last):
  File "C:\Users\User\Desktop\daveblog\venv\Lib\site-packages\flask\app.py", line 1463, in wsgi_app
    response = self.full_dispatch_request()
               ^^^^^^^^^^^^^^^^^^^^^^^^^^^^
  File "C:\Users\User\Desktop\daveblog\venv\Lib\site-packages\flask\app.py", line 872, in full_dispatch_request
    rv = self.handle_user_exception(e)
         ^^^^^^^^^^^^^^^^^^^^^^^^^^^^^
  File "C:\Users\User\Desktop\daveblog\venv\Lib\site-packages\flask\app.py", line 870, in full_dispatch_request
    rv = self.dispatch_request()
         ^^^^^^^^^^^^^^^^^^^^^^^
  File "C:\Users\User\Desktop\daveblog\venv\Lib\site-packages\flask\app.py", line 855, in dispatch_request
    return self.ensure_sync(self.view_functions[rule.endpoint])(**view_args)  # type: ignore[no-any-return]
           ^^^^^^^^^^^^^^^^^^^^^^^^^^^^^^^^^^^^^^^^^^^^^^^^^^^^^^^^^^^^^^^^^
  File "C:\Users\User\Desktop\daveblog\app\routes.py", line 180, in reset_password_request
    return render_template('reset_password_request.html',
           ^^^^^^^^^^^^^^^^^^^^^^^^^^^^^^^^^^^^^^^^^^^^^^
  File "C:\Users\User\Desktop\daveblog\venv\Lib\site-packages\flask\templating.py", line 150, in render_template
    return _render(app, template, context)
           ^^^^^^^^^^^^^^^^^^^^^^^^^^^^^^^
  File "C:\Users\User\Desktop\daveblog\venv\Lib\site-packages\flask\templating.py", line 131, in _render
    rv = template.render(context)
         ^^^^^^^^^^^^^^^^^^^^^^^^
  File "C:\Users\User\Desktop\daveblog\venv\Lib\site-packages\jinja2\environment.py", line 1301, in render
    self.environment.handle_exception()
  File "C:\Users\User\Desktop\daveblog\venv\Lib\site-packages\jinja2\environment.py", line 936, in handle_exception
    raise rewrite_traceback_stack(source=source)
  File "C:\Users\User\Desktop\daveblog\app\templates\reset_password_request.html", line 1, in top-level template code
    {% extends "base.html" %}
  File "C:\Users\User\Desktop\daveblog\app\templates\base.html", line 31, in top-level template code
    {% block content %}{% endblock %}
    ^^^^^^^^^^^^^^^^^^^^^^^^^
  File "C:\Users\User\Desktop\daveblog\app\templates\reset_password_request.html", line 8, in block 'content'
    {{ form.password.label }}<br>
    ^^^^^^^^^^^^^^^^^^^^^^^^^
  File "C:\Users\User\Desktop\daveblog\venv\Lib\site-packages\jinja2\environment.py", line 485, in getattr
    return getattr(obj, attribute)
           ^^^^^^^^^^^^^^^^^^^^^^^
jinja2.exceptions.UndefinedError: 'app.forms.ResetPasswordRequestForm object' has no attribute 'password'
2024-02-26 21:36:08,485 INFO: Microblog startup [in C:\Users\User\Desktop\daveblog\app\__init__.py:47]
2024-02-26 21:40:20,372 INFO: Microblog startup [in C:\Users\User\Desktop\daveblog\app\__init__.py:47]
2024-02-26 21:53:05,894 INFO: Microblog startup [in C:\Users\User\Desktop\daveblog\app\__init__.py:47]
2024-02-26 21:55:50,261 INFO: Microblog startup [in C:\Users\User\Desktop\daveblog\app\__init__.py:47]
2024-02-26 22:04:37,797 INFO: Microblog startup [in C:\Users\User\Desktop\daveblog\app\__init__.py:47]
